Workbook

Sheet takt-time
A1: Parameter | B1: Year 1 | C1: Year 2 | D1: Year 3
A2: Target Annual Production ($U_{year}^{total}$) | B2: 150 | C2: 150 | D2: 200
A3: Working Days per Year ($D_{year}$) | B3: 252 | C3: 252 | D3: 252
A4: Shifts per Day ($N_{shifts}$) | B4: 1 | C4: 1 | D4: 1
A5: Time per Shift ($t_{shift}$) [s] | B5: =7.5*3600 -> 27000 | C5: =7.5*3600 -> 27000 | D5: =7.5*3600 -> 27000
A6: Available Time per Year ($t_{w}$) [s] | B6: =B3*B4*B5 -> 6804000 | C6: =C3*C4*C5 -> 6804000 | D6: =D3*D4*D5 -> 6804000
A7: Takt Time ($T$) [s] | B7: =B6/B2 -> 45360 | C7: =C6/C2 -> 45360 | D7: =D6/D2 -> 34020
A8: Takt Time ($T$) [min] | B8: =B7/60 -> 756 | C8: =C7/60 -> 756 | D8: =D7/60 -> 567
A9: Takt Time ($T$) [hr] | B9: =B7/60/60 -> 12.6 | C9: =C7/60/60 -> 12.6 | D9: =D7/60/60 -> 9.45

Sheet machine-efficiency
A1: Machine | B1: OEE | C1: Ideal Machine Availability [minutes/day] | D1: Real Machine availability [minutes/day] | E1: Real Machine availability [minutes/year]
A2: 3D Printer | B2: 0.55 | C2: 450 | D2: =B2*C2 -> 247.5 | E2: =D2*252 -> 62370
A3: 4-Axis CNC Milling Machine | B3: 0.7 | C3: 450 | D3: =B3*C3 -> 315 | E3: =D3*252 -> 79380
A4: 3-Axis CNC Contour Machine | B4: 0.65 | C4: 450 | D4: =B4*C4 -> 292.5 | E4: =D4*252 -> 73710
A5: 3-Axis CNC Milling Machine | B5: 0.7 | C5: 450 | D5: =B5*C5 -> 315 | E5: =D5*252 -> 79380
A6: Extrusion Press | B6: 0.9 | C6: 450 | D6: =B6*C6 -> 405 | E6: =D6*252 -> 102060
A7: Drill | B7: 0.6 | C7: 450 | D7: =B7*C7 -> 270 | E7: =D7*252 -> 68040
A8: Reamer | B8: 0.5 | C8: 450 | D8: =B8*C8 -> 225 | E8: =D8*252 -> 56700
A9: Laser Cutter | B9: 0.7 | C9: 450 | D9: =B9*C9 -> 315 | E9: =D9*252 -> 79380
A10: Welding Plant | B10: 0.5 | C10: 450 | D10: =B10*C10 -> 225 | E10: =D10*252 -> 56700
A11: Automated Pick-and-Place Machine | B11: 0.75 | C11: 450 | D11: =B11*C11 -> 337.5 | E11: =D11*252 -> 85050
A12: Reflow Oven | B12: 0.85 | C12: 450 | D12: =B12*C12 -> 382.5 | E12: =D12*252 -> 96390
A13: Hand Soldering Station | B13: 0.35 | C13: 450 | D13: =B13*C13 -> 157.5 | E13: =D13*252 -> 39690

Sheet production-time
A1: Position Number | B1: Part | C1: Process(s) | D1: Processing Time [min/unit] | E1: Setup Time [min/unit] | F1: Production Time Per Unit [min/unit] | G1: Production Volume [units/year] | H1: Total Production Time [min/year]
A2: 1 | B2: Printed Circuit Board | C2: Etching, Screen printing | D2: ='production-time-calc'!E4 -> 102 | E2: ='production-time-calc'!F4 -> 15 | F2: =D2+E2 -> 117 | G2: 150 | H2: =F2*G2 -> 17550
A3: 2 | B3: PCB Mount | C3: 3D Printing | D3: ='production-time-calc'!E11 -> 193 | E3: ='production-time-calc'!F11 -> 2 | F3: =D3+E3 -> 195 | G3: 150 | H3: =F3*G3 -> 29250
A4: 3 | B4: Battery Cradle | C4: 3D Printing | D4: ='production-time-calc'!E13 -> 202 | E4: ='production-time-calc'!F13 -> 5 | F4: =D4+E4 -> 207 | G4: 150 | H4: =F4*G4 -> 31050
A5: 4 | B5: Panel Frame | C5: 4-axis CNC Milling | D5: ='production-time-calc'!E15 -> 30 | E5: ='production-time-calc'!F15 -> 16 | F5: =D5+E5 -> 46 | G5: 150 | H5: =F5*G5 -> 6900
A6: 5 | B6: Load Cell Compartment | C6: 3-axis CNC Contour | D6: ='production-time-calc'!E23 -> 35 | E6: ='production-time-calc'!F23 -> 10 | F6: =D6+E6 -> 45 | G6: 150 | H6: =F6*G6 -> 6750
A7: 6 | B7: Aluminium Box Foam | C7: 3-axis CNC Contour | D7: ='production-time-calc'!E24 -> 60 | E7: ='production-time-calc'!F24 -> 15 | F7: =D7+E7 -> 75 | G7: 150 | H7: =F7*G7 -> 11250
A8: 7 | B8: Electronics Basin | C8: Backward Extrusion and 4-axis CNC Milling | D8: ='production-time-calc'!E25 -> 74 | E8: ='production-time-calc'!F25 -> 60 | F8: =D8+E8 -> 134 | G8: 150 | H8: =F8*G8 -> 20100
A9: 8 | B9: Aluminium Frame | C9: Fiber Glass Laser cutting and Manual Welding | D9: ='production-time-calc'!E33 -> 40 | E9: ='production-time-calc'!F33 -> 30 | F9: =D9+E9 -> 70 | G9: 150 | H9: =F9*G9 -> 10500
A10: 9 | B10: Panel | C10: 3-axis CNC Milling | D10: ='production-time-calc'!E38 -> 40 | E10: ='production-time-calc'!F38 -> 25 | F10: =D10+E10 -> 65 | G10: 150 | H10: =F10*G10 -> 9750
A11: 10 | B11: Cable Tray | C11: 3-axis CNC Milling | D11: ='production-time-calc'!E39 -> 20 | E11: ='production-time-calc'!F39 -> 10 | F11: =D11+E11 -> 30 | G11: 150 | H11: =F11*G11 -> 4500
A12: 11 | B12: Top Foam | C12: 3-axis CNC Contour | D12: ='production-time-calc'!E40 -> 8 | E12: ='production-time-calc'!F40 -> 5 | F12: =D12+E12 -> 13 | G12: 150 | H12: =F12*G12 -> 1950
A13: 12 | B13: Lower Pelican Case | C13: Manual Drilling and Reaming | D13: ='production-time-calc'!E41 -> 10 | E13: ='production-time-calc'!F41 -> 10 | F13: =D13+E13 -> 20 | G13: 150 | H13: =F13*G13 -> 3000
A14: 13 | B14: M12 Load Cell Cable | C14: Soldering | D14: ='production-time-calc'!E44 -> 10 | E14: ='production-time-calc'!F44 -> 5 | F14: =D14+E14 -> 15 | G14: 150 | H14: =F14*G14 -> 2250
F15: =SUM(F2:F14) -> 1032

Sheet machine-allocation
A1: Machine | B1: Required Production Time [min/year] | C1: Machine Availability [min/year] | D1: No. of Machines | E1: No. of Machines (estimate)
A2: 3D Printer | B2: ='production-time-calc'!D49 -> 60300 | C2: ='machine-efficiency'!E2 -> 62370 | D2: =_xlfn.CEILING.MATH(E2) -> 1 | E2: =B2/C2 -> 0.96681097
A3: 4-Axis CNC Milling Machine | B3: ='production-time-calc'!D50 -> 24450 | C3: ='machine-efficiency'!E3 -> 79380 | D3: =_xlfn.CEILING.MATH(E3) -> 1 | E3: =B3/C3 -> 0.30801209
A4: 3-Axis CNC Contour Machine | B4: ='production-time-calc'!D51 -> 19950 | C4: ='machine-efficiency'!E4 -> 73710 | D4: =_xlfn.CEILING.MATH(E4) -> 1 | E4: =B4/C4 -> 0.27065527
A5: 3-Axis CNC Milling Machine | B5: ='production-time-calc'!D52 -> 14250 | C5: ='machine-efficiency'!E5 -> 79380 | D5: =_xlfn.CEILING.MATH(E5) -> 1 | E5: =B5/C5 -> 0.17951625
A6: Extrusion Press | B6: ='production-time-calc'!D53 -> 2550 | C6: ='machine-efficiency'!E6 -> 102060 | D6: =_xlfn.CEILING.MATH(E6) -> 1 | E6: =B6/C6 -> 0.024985303
A7: Drill | B7: ='production-time-calc'!D54 -> 2100 | C7: ='machine-efficiency'!E7 -> 68040 | D7: =_xlfn.CEILING.MATH(E7) -> 1 | E7: =B7/C7 -> 0.030864198
A8: Reamer | B8: ='production-time-calc'!D55 -> 2400 | C8: ='machine-efficiency'!E8 -> 56700 | D8: =_xlfn.CEILING.MATH(E8) -> 1 | E8: =B8/C8 -> 0.042328042
A9: Laser Cutter | B9: ='production-time-calc'!D56 -> 3750 | C9: ='machine-efficiency'!E9 -> 79380 | D9: =_xlfn.CEILING.MATH(E9) -> 1 | E9: =B9/C9 -> 0.047241119
A10: Welding Plant | B10: ='production-time-calc'!D57 -> 11550 | C10: ='machine-efficiency'!E10 -> 56700 | D10: =_xlfn.CEILING.MATH(E10) -> 1 | E10: =B10/C10 -> 0.2037037
A11: Automated Pick-and-Place Machine | B11: ='production-time-calc'!D58 -> 1650 | C11: ='machine-efficiency'!E11 -> 85050 | D11: =_xlfn.CEILING.MATH(E11) -> 1 | E11: =B11/C11 -> 0.019400353
A12: Reflow Oven | B12: ='production-time-calc'!D59 -> 3075 | C12: ='machine-efficiency'!E12 -> 96390 | D12: =_xlfn.CEILING.MATH(E12) -> 1 | E12: =B12/C12 -> 0.03190165
A13: Hand Soldering Station | B13: ='production-time-calc'!D60 -> 3750 | C13: ='machine-efficiency'!E13 -> 39690 | D13: =_xlfn.CEILING.MATH(E13) -> 1 | E13: =B13/C13 -> 0.094482237

Sheet workforce
A1: PRODUCTION
A3: Machine | B3: No. of Machines | C3: Required Production Time [h/year] | D3: Required Working Hours [h/day] | E3: Required Shifts [shifts/day]
A4: 3D Printer | B4: ='machine-allocation'!D2 -> 1 | C4: ='production-time-calc'!F49 -> 1005 | D4: ='production-time-calc'!E49 -> 6.7 | E4: =D4/(7.5) -> 0.89333333
A5: 4-Axis CNC Milling Machine | B5: ='machine-allocation'!D3 -> 1 | C5: ='production-time-calc'!F50 -> 407.5 | D5: ='production-time-calc'!E50 -> 2.7166667 | E5: =D5/(7.5) -> 0.36222222
A6: 3-Axis CNC Contour Machine | B6: ='machine-allocation'!D4 -> 1 | C6: ='production-time-calc'!F51 -> 332.5 | D6: ='production-time-calc'!E51 -> 2.2166667 | E6: =D6/(7.5) -> 0.29555556
A7: 3-Axis CNC Milling Machine | B7: ='machine-allocation'!D5 -> 1 | C7: ='production-time-calc'!F52 -> 237.5 | D7: ='production-time-calc'!E52 -> 1.5833333 | E7: =D7/(7.5) -> 0.21111111
A8: Extrusion Press | B8: ='machine-allocation'!D6 -> 1 | C8: ='production-time-calc'!F53 -> 42.5 | D8: ='production-time-calc'!E53 -> 0.28333333 | E8: =D8/(7.5) -> 0.037777778
A9: Drill | B9: ='machine-allocation'!D7 -> 1 | C9: ='production-time-calc'!F54 -> 35 | D9: ='production-time-calc'!E54 -> 0.23333333 | E9: =D9/(7.5) -> 0.031111111
A10: Reamer | B10: ='machine-allocation'!D8 -> 1 | C10: ='production-time-calc'!F55 -> 40 | D10: ='production-time-calc'!E55 -> 0.26666667 | E10: =D10/(7.5) -> 0.035555556
A11: Laser Cutter | B11: ='machine-allocation'!D9 -> 1 | C11: ='production-time-calc'!F56 -> 62.5 | D11: ='production-time-calc'!E56 -> 0.41666667 | E11: =D11/(7.5) -> 0.055555556
A12: Welding Plant | B12: ='machine-allocation'!D10 -> 1 | C12: ='production-time-calc'!F57 -> 192.5 | D12: ='production-time-calc'!E57 -> 1.2833333 | E12: =D12/(7.5) -> 0.17111111
A13: Hand Soldering Station | B13: ='machine-allocation'!D13 -> 1 | C13: ='production-time-calc'!F58 -> 27.5 | D13: ='production-time-calc'!E58 -> 0.18333333 | E13: =D13/(7.5) -> 0.024444444
D14: =SUM(D4:D13) -> 15.883333 | E14: =SUM(E4:E13) -> 2.1177778
A19: ASSEMBLY
A20: Assembly Station | B20: Required Assembly Time [h/year] | C20: Required Working Hours [h/day] | D20: Required Shifts [shifts/day] | F20: Required Assembly Time [min/unit]
A21: Line 1 – Basin Assembly | B21: =(F21*150)/60 -> 145 | C21: =B21/252 -> 0.57539683 | D21: =C21/7.5 -> 0.076719577 | F21: =SUM('assembly-stations'!$F$4:$F$13) -> 58
A22: Line 2 – Top Panel Assembly | B22: =(F22*150)/60 -> 45 | C22: =B22/252 -> 0.17857143 | D22: =C22/7.5 -> 0.023809524 | F22: =SUM('assembly-stations'!$F$14:$F$15) -> 18
A23: Line 3 – Electronics interior assembly | B23: =(F23*150)/60 -> 47.5 | C23: =B23/252 -> 0.18849206 | D23: =C23/7.5 -> 0.025132275 | F23: ='assembly-stations'!$F$16+'assembly-stations'!$F$17 -> 19
A24: Line 4 – Panel frame assembly | B24: =(F24*150)/60 -> 7.5 | C24: =B24/252 -> 0.029761905 | D24: =C24/7.5 -> 0.003968254 | F24: ='assembly-stations'!$F$18 -> 3
A25: Line 5 – Pelican case assembly | B25: =(F25*150)/60 -> 17.5 | C25: =B25/252 -> 0.069444444 | D25: =C25/7.5 -> 0.0092592593 | F25: =SUM('assembly-stations'!$F$19:$F$21) -> 7
A26: Line 6 – Final assembly | B26: =(F26*150)/60 -> 5 | C26: =B26/252 -> 0.01984127 | D26: =C26/7.5 -> 0.0026455026 | F26: ='assembly-stations'!$F$22 -> 2
C27: =SUM(C21:C26) -> 1.0615079 | D27: =SUM(D21:D26) -> 0.14153439
A29: WORKFORCE
A30: Hrs | B30: =_xlfn.CEILING.MATH(C27+D14) -> 17 | C30: =252*B30 -> 4284
A31: Shifts | B31: =_xlfn.CEILING.MATH(D27+E14) -> 3 | C31: =252*B31*7.5 -> 5670

Sheet production-time-calc
A1: PRODUCTION
A3: Position Number | B3: Part | C3: Process Steps | D3: Process Step Time [min] | E3: Processing Time Per Unit [min/unit] | F3: Setup Time Per Unit [min/unit] | G3: Total Time [min/unit] | K3: Notes
A4: 1 | B4: Printed Circuit Board | C4: Cutting | D4: 2 | E4: =SUM(D4:D9) -> 102 | F4: =D10 -> 15 | G4: =E4+F4 -> 117
C5: Treatment | D5: 10
C6: Etching | D6: 40
C7: Drilling | D7: 10
C8: Surface Finish | D8: 20
C9: Screen Printing | D9: 20
C10: Transfering between stations | D10: 15
A11: 2 | B11: PCB Mount | C11: 3D Printing | D11: 193 | E11: =SUM(D11) -> 193 | F11: =D12 -> 2 | G11: =E11+F11 -> 195 | K11: 0.2mm layer, quality, 70% infill w/ supportts
C12: Support removal | D12: 2
A13: 3 | B13: Battery Cradle | C13: 3D Printing | D13: 202 | E13: =SUM(D13) -> 202 | F13: =D14 -> 5 | G13: =E13+F13 -> 207 | K13: 0.2mm layer, quality, 30% infill w/ supportts
C14: Support removal | D14: 5
A15: 4 | B15: Panel Frame | C15: Secure workpiece | D15: 5 | E15: =D16+D18+D20+D22 -> 30 | F15: =D15+D17+D19+D21 -> 16 | G15: =E15+F15 -> 46
C16: Center cut out | D16: 6
C17: Remove center piece | D17: 3
C18: Feature milling | D18: 18
C19: Rotate workpiece | D19: 4
C20: Milling holes | D20: 3
C21: Rotate workpiece | D21: 4
C22: Milling holes | D22: 3
A23: 5 | B23: Load Cell Compartment | C23: 3-axis CNC Contour | E23: 35 | F23: 10 | G23: =E23+F23 -> 45
A24: 6 | B24: Aluminium Box Foam | C24: 3-axis CNC Contour | E24: 60 | F24: 15 | G24: =E24+F24 -> 75
A25: 7 | B25: Electronics Basin | C25: Secure workpiece | D25: 10 | E25: =D26+D29+D31+D32 -> 74 | F25: =D25+D27+D28+D30 -> 60 | G25: =E25+F25 -> 134
C26: Extrusion Process | D26: 2
C27: Remove workpiece | D27: 5
C28: Transfer piece to CNC Mill | D28: 25
C29: Milling groves (x4) | D29: 40
C30: Rotating (x4) | D30: 20
C31: Milling hole | D31: 2
C32: Finishing (x4) w/ grinder | D32: 30
A33: 8 | B33: Aluminium Frame | C33: Loading laser cutter | D33: 10 | E33: =D34+D37 -> 40 | F33: =D33+D35+D36 -> 30 | G33: =E33+F33 -> 70
C34: Laser cutting | D34: 10
C35: Collect workpieces | D35: 5
C36: Setup and secure workpieces | D36: 15
C37: Weld work pieces | D37: 30
A38: 9 | B38: Panel | C38: 3-axis CNC Milling | E38: 40 | F38: 25 | G38: =E38+F38 -> 65
A39: 10 | B39: Cable Tray | C39: 3-axis CNC Milling | E39: 20 | F39: 10 | G39: =E39+F39 -> 30
A40: 11 | B40: Top Foam | C40: 3-axis CNC Contour | E40: 8 | F40: 5 | G40: =E40+F40 -> 13
A41: 12 | B41: Lower Pelican Case | C41: Secure workpiece | D41: 10 | E41: =D42+D43 -> 10 | F41: =D41 -> 10 | G41: =E41+F41 -> 20
...

Sheet assembly-stations
A3: Assembly Station | B3: Sub assembly station | C3: Parts assembly | D3: Assembly Process | E3: No. of Machines | F3: Total Time (mins) | I3: Assembly Lines
A4: Line 1 – Basin Assembly | B4: Line 1.1 – PCB Assembly (A1) | C4: Part 1 and all electrical components (Table 27, except USB C and M12 port) | D4: Place solder paste using stencil | E4: 1 | F4: 50 | I4: Y1 | J4: =$F$23/'takt-time'!B$8 -> 0.14153439
D5: Place all components (Automated pick and place machine) | I5: Y2 | J5: =$F$23/'takt-time'!C$8 -> 0.14153439
D6: Solder (Reflow oven) | I6: Y3 | J6: =$F$23/'takt-time'!D$8 -> 0.18871252
B7: Line 1.2 – PCB mount assembly (A3) | C7: 1, 2, 16 and 22 | D7: Screw PCB into Mount | E7: - | F7: 1
B8: Line 1.3 – Battery Cradle Assembly (A2) | C8: 3 and 25 | D8: Strap Velcro onto cradle | E8: - | F8: 1
B9: Line 1.4 – | C9: 2, 7, 17 and 21 | D9: Screw the battery cradle in | E9: - | F9: 1
B10: Battery cradle into basin (A6)
B11: Line 1.5 – M12 port into basin (A8) | C11: 7, 13 and M12 gasket | D11: Insert M12 port into the basin | E11: - | F11: 1
B12: Line 1.6 – PCB Mount into basin (A7) | C12: 2, 7 and 27 | D12: Tape the PCB mount onto the wall | E12: - | F12: 2
B13: Line 1.7 – Frame and gasket onto basin (A9 & A10) | C13: 7, 8, Battery, 17 , 21, 24 and 26 | D13: Place in the battery, then place gasket and screw frame on to the basin | E13: - | F13: 2
A14: Line 2 – Top Panel Assembly | B14: Line 2.1 – Top Panel welding (A4) | C14: 9 and 10 | D14: Weld cable tray onto top panel | E14: 1 | F14: 14
B15: Line 2.2 – Buttons and ports insertion | C15: SW1, SW2, J2, D2, 9, 18 and 24 | D15: Screw the buttons, LEDs and USB A port into the top panel | E15: - | F15: 4
A16: Line 3 – Electronics interior assembly | B16: Line 3.1 – Top panel and basin assembly (A11) | C16: 7 and 9 | D16: Weld top panel and basin together | E16: 1 | F16: 18
B17: Line 3.2 – Screen insertion (A12) | C17: 7, EDPM Foam tape and U12 | D17: Insert screen and tape for sealing | E17: - | F17: 1
A18: Line 4 – Panel frame assembly | B18: (A14) | C18: 4 and 20 | D18: Insert rivets into panel frame | E18: - | F18: 3
A19: Line 5 – Pelican case assembly | B19: Line 5.1 – USB C port insertion (A13) | C19: J3 and 12 | D19: Insert USB – C port | E19: - | F19: 1
B20: Line 5.2 – screw in panel frame (A15 & A16) | C20: 4, 5, 6, 11, 12 and 19 and glue | D20: Insert foam into case, then screw in panel frame | E20: - | F20: 4
B21: Line 5.3 – electronics insertion (A17) | C21: 7, 12 and O-ring | D21: Screw in electronics with O-ring | E21: - | F21: 2
A22: Line 6 – Final assembly | B22: A18 | C22: 12 and load cells and cables | D22: Keep the load cells and cables in and close the box | E22: - | F22: 2
F23: =SUM(F4:F22) -> 107
