Workbook
Name _ftn1: BOM_word!$A$34
Name _ftnref1: BOM_word!$E$1

Sheet BOM_word
A1: Position Number | B1: Part Name | C1: Material | D1: Qty | E1: Standard[1] | G1: Verified (from SW) | H1: Verified (from Ahmad)
A2: 2 | B2: PCB Mount | C2: General Purpose Polycarbonate | D2: 1 | E2: ISO 21305-1:2019 | G2: TRUE | H2: FALSE
A3: 3 | B3: Battery Cradle | C3: Heat resistant ABS | D3: 1 | E3: ISO 2580-1 ABS | G3: TRUE | H3: TRUE
A4: 4 | B4: Panel Frame | C4: 5052 Aluminium | D4: 1 | E4: ISO: Al-Mg2,5 | G4: TRUE | H4: TRUE
A5: 5 | B5: Load Cell Compartment | C5: Medium Density EVA Foam | D5: 1 | E5: Make | G5: TRUE | H5: TRUE
A6: 6 | B6: Aluminium Box Foam | C6: Medium Density EVA Foam | D6: 1 | E6: Make | G6: TRUE | H6: TRUE
A7: 7 | B7: Electronics Basin | C7: 5052 Aluminium | D7: 1 | E7: ISO: Al-Mg2,5 | G7: TRUE | H7: TRUE
A8: 8 | B8: Aluminium Frame | C8: 5052 Aluminium | D8: 1 | E8: ISO: Al-Mg2,5 | G8: TRUE | H8: TRUE
A9: 9 | B9: Panel | C9: 5052 Aluminium | D9: 1 | E9: ISO: Al-Mg2,5 | G9: TRUE | H9: TRUE
A10: 10 | B10: Cable Tray | C10: 5052 Aluminium | D10: 1 | E10: ISO: Al-Mg2,5 | G10: TRUE | H10: TRUE
A11: 11 | B11: Top Foam | C11: Medium Density EVA Foam | D11: 1 | E11: Make | G11: TRUE | H11: TRUE
A12: 12 | B12: Pelican Case | C12: Polypropylene | D12: 1 | E12: Modify | G12: TRUE | H12: TRUE
A13: 27 | B13: M4 x 0.7 x 12 Button Head Screws | D13: 12 | E13: ISO 7380 | G13: TRUE | H13: TRUE
A14: 28 | B14: M3 x 0.5 x 10 Button Head Screws | D14: 4 | E14: ISO 7380 | G14: TRUE | H14: TRUE
A15: 29 | B15: M3 x 0.5 x 8 Button Head Screws | D15: 12 | E15: ISO 7380 | G15: TRUE | H15: TRUE
A16: 30 | B16: M3 x 0.5 x 6 Button Head Screws | D16: 2 | E16: ISO 7380 | G16: TRUE | H16: TRUE
A17: 31 | B17: M2 x 0.4 x 16 Slotted Pan Head Screw | D17: 4 | E17: ISO 1580 | G17: TRUE | H17: TRUE
A18: 32 | B18: ST2.9 x 9.5 Tapping Screws | D18: 4 | E18: ISO 14585 | G18: TRUE | H18: TRUE
A19: 33 | B19: M4 x 0.7 x 9.2 Rivet Nuts | D19: 12 | G19: TRUE | H19: TRUE
A20: 34 | B20: M3 x 0.5 Hex Nuts | D20: 16 | E20: ISO 4032 | G20: TRUE | H20: TRUE
A21: 35 | B21: M2 x 0.4 Hex Nuts | D21: 4 | E21: ISO 4035 | G21: TRUE | H21: TRUE
A22: 36 | B22: M4 Washers | D22: 12 | E22: ISO 7092 | G22: TRUE | H22: TRUE
A23: 37 | B23: M3 Washers | D23: 18 | E23: ISO 7092 | G23: TRUE | H23: TRUE
A24: 38 | B24: O-ring | C24: Silicone Rubber | D24: 1 | G24: TRUE | H24: TRUE
A25: 39 | B25: Seal for Screen Bezel | C25: PVC Foam Tape | D25: 1 | G25: TRUE | H25: TRUE
A26: 40 | B26: Aluminium Frame Gasket | C26: PVC Foam Tape | D26: 1 | G26: TRUE | H26: TRUE
A27: 41 | B27: USB C Gasket | C27: Built into bought product | D27: 1 | G27: TRUE | H27: TRUE
A28: 42 | B28: M12 Gasket | C28: PVC Foam Tape | D28: 1 | G28: TRUE | H28: TRUE
A29: 43 | B29: Velcro Roll | C29: Velcro | D29: 1 | G29: TRUE | H29: TRUE
A30: 44 | B30: PVC Foam Tape | D30: 1 | G30: FALSE | H30: FALSE
A31: 45 | B31: 3M Scotch-Weld Epoxy DP420 | D31: 1 | G31: FALSE | H31: FALSE
A34: [1] For custom “Make” parts, the ISO standard refers to the material while for “Buy” parts it is the design of the machine element itself
A38: 1 | B38: Printed Circuit Board | C38: Würth Elektronik | D38: 1
A39: 13 | B39: M12 Load Cell Cable | C39: Binder | D39: 1
A40: 14 | B40: TouchScreen/SPI Touch Controller | C40: EastRising | D40: 1
A41: 15 | B41: Push Buttons | C41: Metzler | D41: 2
A42: 16 | B42: M12 5-pin | C42: Phoenix Contact | D42: 1
A43: 17 | B43: USB A | C43: Stewart Connector | D43: 1
A44: 18 | B44: USB C | C44: Stewart Connector | D44: 1
A45: 19 | B45: Bi-colour LED Light Pipe | C45: Bivar | D45: 1
...

Sheet BOM_template
A1: =BOM_word!A38 -> 1 | B1: =BOM_word!D38 -> 1 | C1: =BOM_word!B38 -> Printed Circuit Board | F1: 00 | G1: FR-4 and Copper
A2: =BOM_word!A2 -> 2 | B2: =BOM_word!D2 -> 1 | C2: =BOM_word!B2 -> PCB Mount | D2: =BOM_word!E2 -> ISO 21305-1:2019 | F2: 00 | G2: =BOM_word!C2 -> General Purpose Polycarbonate
A3: =BOM_word!A3 -> 3 | B3: =BOM_word!D3 -> 1 | C3: =BOM_word!B3 -> Battery Cradle | D3: =BOM_word!E3 -> ISO 2580-1 ABS | F3: 00 | G3: =BOM_word!C3 -> Heat resistant ABS
A4: =BOM_word!A4 -> 4 | B4: =BOM_word!D4 -> 1 | C4: =BOM_word!B4 -> Panel Frame | D4: =BOM_word!E4 -> ISO: Al-Mg2,5 | F4: 00 | G4: =BOM_word!C4 -> 5052 Aluminium
A5: =BOM_word!A5 -> 5 | B5: =BOM_word!D5 -> 1 | C5: =BOM_word!B5 -> Load Cell Compartment | D5: =BOM_word!E5 -> Make | F5: 00 | G5: =BOM_word!C5 -> Medium Density EVA Foam
A6: =BOM_word!A6 -> 6 | B6: =BOM_word!D6 -> 1 | C6: =BOM_word!B6 -> Aluminium Box Foam | D6: =BOM_word!E6 -> Make | F6: 00 | G6: =BOM_word!C6 -> Medium Density EVA Foam
A7: =BOM_word!A7 -> 7 | B7: =BOM_word!D7 -> 1 | C7: =BOM_word!B7 -> Electronics Basin | D7: =BOM_word!E7 -> ISO: Al-Mg2,5 | F7: 00 | G7: =BOM_word!C7 -> 5052 Aluminium
A8: =BOM_word!A8 -> 8 | B8: =BOM_word!D8 -> 1 | C8: =BOM_word!B8 -> Aluminium Frame | D8: =BOM_word!E8 -> ISO: Al-Mg2,5 | F8: 00 | G8: =BOM_word!C8 -> 5052 Aluminium
A9: =BOM_word!A9 -> 9 | B9: =BOM_word!D9 -> 1 | C9: =BOM_word!B9 -> Panel | D9: =BOM_word!E9 -> ISO: Al-Mg2,5 | F9: 00 | G9: =BOM_word!C9 -> 5052 Aluminium
A10: =BOM_word!A10 -> 10 | B10: =BOM_word!D10 -> 1 | C10: =BOM_word!B10 -> Cable Tray | D10: =BOM_word!E10 -> ISO: Al-Mg2,5 | F10: 00 | G10: =BOM_word!C10 -> 5052 Aluminium
A11: =BOM_word!A11 -> 11 | B11: =BOM_word!D11 -> 1 | C11: =BOM_word!B11 -> Top Foam | D11: =BOM_word!E11 -> Make | F11: 00 | G11: =BOM_word!C11 -> Medium Density EVA Foam
A12: =BOM_word!A12 -> 12 | B12: =BOM_word!D12 -> 1 | C12: =BOM_word!B12 -> Pelican Case | D12: =BOM_word!E12 -> Modify | F12: 00 | G12: =BOM_word!C12 -> Polypropylene
A13: =BOM_word!A39 -> 13 | B13: =BOM_word!D39 -> 1 | C13: =BOM_word!B39 -> M12 Load Cell Cable | F13: 00
A14: =BOM_word!A40 -> 14 | B14: =BOM_word!D40 -> 1 | C14: =BOM_word!B40 -> TouchScreen/SPI Touch Controller | F14: 00
A15: =BOM_word!A41 -> 15 | B15: =BOM_word!D41 -> 2 | C15: =BOM_word!B41 -> Push Buttons | F15: 00
A16: =BOM_word!A42 -> 16 | B16: =BOM_word!D42 -> 1 | C16: =BOM_word!B42 -> M12 5-pin | F16: 00
A17: =BOM_word!A43 -> 17 | B17: =BOM_word!D43 -> 1 | C17: =BOM_word!B43 -> USB A | F17: 00
A18: =BOM_word!A44 -> 18 | B18: =BOM_word!D44 -> 1 | C18: =BOM_word!B44 -> USB C | F18: 00
A19: =BOM_word!A45 -> 19 | B19: =BOM_word!D45 -> 1 | C19: =BOM_word!B45 -> Bi-colour LED Light Pipe | F19: 00
A20: =BOM_word!A46 -> 20 | B20: =BOM_word!D46 -> 1 | C20: =BOM_word!B46 -> Battery | F20: 00
A21: =BOM_word!A47 -> 21 | B21: =BOM_word!D47 -> 1 | C21: =BOM_word!B47 -> 150 gf Load Cell | F21: 00
A22: =BOM_word!A48 -> 22 | B22: =BOM_word!D48 -> 1 | C22: =BOM_word!B48 -> 2 kgf Load Cell | F22: 00
A23: =BOM_word!A49 -> 23 | B23: =BOM_word!D49 -> 1 | C23: =BOM_word!B49 -> 20 kgf Load Cell | F23: 00
A24: =BOM_word!A50 -> 24 | B24: =BOM_word!D50 -> 1 | C24: =BOM_word!B50 -> 45 kgf Load Cell | F24: 00
... A26: =BOM_word!A52 -> 26 | B26: =BOM_word!D52 -> 1 | C26: =BOM_word!B52 -> 3000 kgf Load Cell | F26: 00
A27: =BOM_word!A13 -> 27 | B27: =BOM_word!D13 -> 12 | C27: =BOM_word!B13 -> M4 x 0.7 x 12 Button Head Screws | D27: =BOM_word!E13 -> ISO 7380 | F27: 00 | G27: =BOM_word!C13 -> 0
A28: =BOM_word!A14 -> 28 | B28: =BOM_word!D14 -> 4 | C28: =BOM_word!B14 -> M3 x 0.5 x 10 Button Head Screws | D28: =BOM_word!E14 -> ISO 7380 | F28: 00 | G28: =BOM_word!C14 -> 0
A29: =BOM_word!A15 -> 29 | B29: =BOM_word!D15 -> 12 | C29: =BOM_word!B15 -> M3 x 0.5 x 8 Button Head Screws | D29: =BOM_word!E15 -> ISO 7380 | F29: 00 | G29: =BOM_word!C15 -> 0
A30: =BOM_word!A16 -> 30 | B30: =BOM_word!D16 -> 2 | C30: =BOM_word!B16 -> M3 x 0.5 x 6 Button Head Screws | D30: =BOM_word!E16 -> ISO 7380 | F30: 00 | G30: =BOM_word!C16 -> 0
A31: =BOM_word!A17 -> 31 | B31: =BOM_word!D17 -> 4 | C31: =BOM_word!B17 -> M2 x 0.4 x 16 Slotted Pan Head Screw | D31: =BOM_word!E17 -> ISO 1580 | F31: 00 | G31: =BOM_word!C17 -> 0
A32: =BOM_word!A18 -> 32 | B32: =BOM_word!D18 -> 4 | C32: =BOM_word!B18 -> ST2.9 x 9.5 Tapping Screws | D32: =BOM_word!E18 -> ISO 14585 | F32: 00 | G32: =BOM_word!C18 -> 0
A33: =BOM_word!A19 -> 33 | B33: =BOM_word!D19 -> 12 | C33: =BOM_word!B19 -> M4 x 0.7 x 9.2 Rivet Nuts | D33: =BOM_word!E19 -> 0 | F33: 00 | G33: =BOM_word!C19 -> 0
A34: =BOM_word!A20 -> 34 | B34: =BOM_word!D20 -> 16 | C34: =BOM_word!B20 -> M3 x 0.5 Hex Nuts | D34: =BOM_word!E20 -> ISO 4032 | F34: 00 | G34: =BOM_word!C20 -> 0
A35: =BOM_word!A21 -> 35 | B35: =BOM_word!D21 -> 4 | C35: =BOM_word!B21 -> M2 x 0.4 Hex Nuts | D35: =BOM_word!E21 -> ISO 4035 | F35: 00 | G35: =BOM_word!C21 -> 0
A36: =BOM_word!A22 -> 36 | B36: =BOM_word!D22 -> 12 | C36: =BOM_word!B22 -> M4 Washers | D36: =BOM_word!E22 -> ISO 7092 | F36: 00 | G36: =BOM_word!C22 -> 0
A37: =BOM_word!A23 -> 37 | B37: =BOM_word!D23 -> 18 | C37: =BOM_word!B23 -> M3 Washers | D37: =BOM_word!E23 -> ISO 7092 | F37: 00 | G37: =BOM_word!C23 -> 0
A38: =BOM_word!A24 -> 38 | B38: =BOM_word!D24 -> 1 | C38: =BOM_word!B24 -> O-ring | D38: =BOM_word!E24 -> 0 | F38: 00 | G38: =BOM_word!C24 -> Silicone Rubber
... A45: =BOM_word!A31 -> 45 | B45: =BOM_word!D31 -> 1 | C45: =BOM_word!B31 -> 3M Scotch-Weld Epoxy DP420 | D45: =BOM_word!E31 -> 0 | F45: 00 | G45: =BOM_word!C31 -> 0
A46: item | B46: qty. | C46: description | D46: specification | E46: drawing no. | F46: rev. | G46: material

Sheet BOM_SW
A1: ITEM NO. | B1: PART NUMBER | C1: DESCRIPTION | D1: QTY. | E1: Added
A2: 1 | B2: 1500bot- rev G | D2: 1 | E2: TRUE
A3: 2 | B3: 1501-931T-CLR | D3: 1 | E3: TRUE
A4: 3 | B4: Aluminum Box Pt 1 | D4: 1 | E4: TRUE
A5: 4 | B5: Aluminum Box Pt 2 | D5: 1 | E5: TRUE
A6: 5 | B6: gasket | D6: 1 | E6: TRUE
A7: 6 | B7: Washer ISO 7092 - 3 | D7: 18 | E7: TRUE
A8: 7 | B8: ISO 7380 - M3 x 8 - 8N | D8: 12 | E8: TRUE
A9: 8 | B9: ISO - 4032 - M3 - W - N | D9: 16 | E9: TRUE
A10: 9 | B10: panel | D10: 1 | E10: TRUE
A11: 10 | B11: 1500-PF | D11: 1 | E11: TRUE
A12: 11 | B12: O-Ring | D12: 1 | E12: TRUE
A13: 12 | B13: Compartment for Cables n other stuff idk what to call it | D13: 1 | E13: TRUE
... A16: 15 | B16: PushButton_P19-TF- POWER-RGB | D16: 2 | E16: TRUE
A17: 16 | B17: SS-52200-001 | D17: 1 | E17: TRUE | F17: USB A
A18: 17 | B18: PLTR5-8MM-PR1 | D18: 1 | E18: TRUE | F18: LED
A19: 18 | B19: ISO 7380 - M3 x 6 - 6N | D19: 2 | E19: TRUE
A20: 19 | B20: Battery Cradle | D20: 1 | E20: TRUE
A21: 20 | B21: Lipo Battery 7000 mAh | D21: 1 | E21: TRUE
A22: 21 | B22: Velcro Strap | D22: 1 | E22: TRUE
A23: 22 | B23: ISO 7380 - M3 x 10 - 10N | D23: 4 | E23: TRUE | F23: button head screws
A24: 23 | B24: Load Cell Compartment | D24: 1 | E24: TRUE
A25: 24 | B25: LC-40-0003 - 3D CAD load cell pancake 3000 kgf (F3000K) | D25: 1 | E25: TRUE
A26: 25 | B26: LC-40-0005 - 3D CAD load cell pancake 250 kgf (F250K) | D26: 1 | E26: TRUE
A27: 26 | B27: LC-40-0007 - 3D CAD load cell donut B 20 kgf (E20K) | D27: 1 | E27: TRUE
A28: 27 | B28: LC-40-4502 - 3D CAD load cell donut A 45 kgf (D45K) | D28: 1 | E28: TRUE
A29: 28 | B29: SA-01-0041 - LC-40- 0006 - 3D CAD load cell flat 150 gf (A151) | D29: 1 | E29: TRUE
A30: 29 | B30: SA-01-0050 - LC-40- 0202 - 3D CAD load cell flat 2 kgf (C202) | D30: 1 | E30: TRUE
A31: 30 | B31: Washer ISO 7092 - 4 | D31: 12 | E31: TRUE
A32: 31 | B32: ISO 7380 - M4 x 12 - 12N | D32: 12 | E32: TRUE
A33: 32 | B33: M4 x 10 Rivet | D33: 12 | E33: TRUE
A34: 33 | B34: Foam Around Aluminum Box | D34: 1 | E34: TRUE
A35: 34 | B35: Board Mount | D35: 1 | E35: TRUE
... A39: 38 | B39: Tapping Screw ISO 14585 - ST2.9 x 9.5- C-N | D39: 4 | E39: TRUE
A40: 39 | B40: SS-52400- 012_1_ASM-0.stp | C40: NOT SPECIFIED | D40: 1 | E40: TRUE
A41: 40 | B41: SS-52400- 012_GASKET.stp | C41: NOT SPECIFIED | D41: 1 | E41: TRUE
A42: 41 | B42: Gasket For M12 | D42: 1 | E42: TRUE
A43: 42 | B43: Hinge Rod | D43: 2 | E43: TRUE
A44: 43 | B44: Case Handle | D44: 1 | E44: TRUE
A45: 44 | B45: Handle Rod | D45: 2 | E45: TRUE
...

Sheet BOM_elec
A1: Reference | B1: Part | C1: Brand | D1: Quantity | E1: Cost per unit | F1: Cost
A2: BT1 | B2: Battery Terminal (XT90PW) | C2: AMASS | D2: 1
A3: C1, C23 | B3: Voltage Blocking Capacitor (ECA-1HM101B) | C3: Panasonic | D3: 2
A4: C2, C4, C5, C6, C8, C10, C13, C15, C19, C20, C27, C33, C40 | B4: Decoupling Capacitor (GRT21BR71H104KE01L) | C4: Murata | D4: 13
A5: C3 | B5: Filter Capacitor (GRM21BR71C105KA01K) | C5: Murata | D5: 1
A6: C7, C9, C11, C12, C24, C25, C26, C28, C34, C35, C37, C41 | B6: Decoupling Capacitor (GCJ31CR71C106KA15K) | C6: Murata | D6: 12
A7: C14 | B7: Filter Capacitor (GCM21BR71C335KA73L) | C7: Murata | D7: 1
A8: C16 | B8: Filter Capacitor (GRM21BR71C475KE51L) | C8: Murata | D8: 1
A9: C17 | B9: Filter Capacitor (GRM21BR71C334JA01L) | C9: Murata | D9: 1
A10: C18 | B10: Filter Capacitor (GRM219R71C474JA01D) | C10: Murata | D10: 1
A11: C21 | B11: Capacitor (GCQ0335C1H100JB01D) | C11: Murata | D11: 1
A12: C22 | B12: Capacitor (GRJ21AR72E102KWJ1D) | C12: Murata | D12: 1
A13: C29 | B13: Capacitor (GRM21AR7LU332KW01D) | C13: Murata | D13: 1
... A16: D1 | B16: ESD Diode | C16: Vishay | D16: 1
B17: (SMF5V0A)
A18: 19 | B18: Bi-colour LED Light Pipe | C18: Bivar | D18: 1
A19: (D2 in 10.3.1 Schematic) | B19: (PLTR5-8MM-PR1)
A20: D3, D4 | B20: Schottky Diode | C20: STMicro-electronics | D20: 2
B21: (STPS340S)
A22: IC1 | B22: Charging Controller (MCP73223) | C22: Microchip | D22: 1
A23: IC2 | B23: Voltage Reference (MAX6126) | C23: Maxim Integrated | D23: 1
A24: L1, L3, L4 | B24: Inductor | C24: Delevan | D24: 3
B25: (8532R-09K)
A26: L2 | B26: Inductor | C26: Bourns | D26: 1
B27: (RLB0913-2R2K)
A28: Q1, Q2, Q5 | B28: P-Channel MOSFET | C28: Alpha & Omega | D28: 3
B29: (AO3401A)
A30: Q3, Q4, Q6 | B30: N-Channel MOSFET | C30: Alpha & Omega | D30: 3
B31: (AO3400A)
A32: R1, R2 | B32: Resistor (TNPW08055K10FETA) | C32: Vishay | D32: 2
A33: R3 | B33: Resistor (ROX050500KFKLB) | C33: Vishay | D33: 1
A34: R4 | B34: Resistor | C34: Xicon | D34: 1
B35: (271-24.3K-AP-RC)
A36: R5 | B36: Resistor | C36: YAGEO | D36: 1
B37: (RSF200JR-52-200K)
A38: R6, R9, R10 | B38: Precision Resistor | C38: Panasonic | D38: 3
B39: (ERA-3AEB103V)
A40: R12, R13, R15, R20, R21, R24, R25, R26, R30, R31, R34, R35 | B40: Resistor | C40: YAGEO | D40: 11
B41: (RSF50SJT-52-10K)
A42: R7 | B42: Precision Resistor | C42: Panasonic | D42: 1
...
